[2025-05-19T22:36:19.541+0000] {taskinstance.py:1956} INFO - Dependencies all met for dep_context=non-requeueable deps ti=<TaskInstance: flight_price_analysis.validate_data manual__2025-05-19T22:26:04.163335+00:00 [queued]>
[2025-05-19T22:36:19.551+0000] {taskinstance.py:1956} INFO - Dependencies all met for dep_context=requeueable deps ti=<TaskInstance: flight_price_analysis.validate_data manual__2025-05-19T22:26:04.163335+00:00 [queued]>
[2025-05-19T22:36:19.552+0000] {taskinstance.py:2170} INFO - Starting attempt 2 of 2
[2025-05-19T22:36:19.575+0000] {taskinstance.py:2191} INFO - Executing <Task(PythonOperator): validate_data> on 2025-05-19 22:26:04.163335+00:00
[2025-05-19T22:36:19.579+0000] {standard_task_runner.py:60} INFO - Started process 1553 to run task
[2025-05-19T22:36:19.582+0000] {standard_task_runner.py:87} INFO - Running: ['***', 'tasks', 'run', 'flight_price_analysis', 'validate_data', 'manual__2025-05-19T22:26:04.163335+00:00', '--job-id', '16', '--raw', '--subdir', 'DAGS_FOLDER/flight_price_pipeline.py', '--cfg-path', '/tmp/tmpq8vebjqe']
[2025-05-19T22:36:19.583+0000] {standard_task_runner.py:88} INFO - Job 16: Subtask validate_data
[2025-05-19T22:36:19.622+0000] {task_command.py:423} INFO - Running <TaskInstance: flight_price_analysis.validate_data manual__2025-05-19T22:26:04.163335+00:00 [running]> on host fb9c3f11be12
[2025-05-19T22:36:19.691+0000] {taskinstance.py:2480} INFO - Exporting env vars: AIRFLOW_CTX_DAG_OWNER='***' AIRFLOW_CTX_DAG_ID='flight_price_analysis' AIRFLOW_CTX_TASK_ID='validate_data' AIRFLOW_CTX_EXECUTION_DATE='2025-05-19T22:26:04.163335+00:00' AIRFLOW_CTX_TRY_NUMBER='2' AIRFLOW_CTX_DAG_RUN_ID='manual__2025-05-19T22:26:04.163335+00:00'
[2025-05-19T22:36:19.700+0000] {base.py:83} INFO - Using connection ID 'mysql_conn' for task execution.
[2025-05-19T22:36:19.711+0000] {warnings.py:109} WARNING - /home/***/.local/lib/python3.8/site-packages/***/providers/common/sql/hooks/sql.py:221: UserWarning: pandas only supports SQLAlchemy connectable (engine/connection) or database string URI or sqlite3 DBAPI2 connection. Other DBAPI2 objects are not tested. Please consider using SQLAlchemy.
  return psql.read_sql(sql, con=conn, params=parameters, **kwargs)

[2025-05-19T22:36:19.713+0000] {data_validation.py:160} ERROR - Error in validate_flight_data: Execution failed on sql 'SELECT * FROM flight_data WHERE Processed = 0': (1054, "Unknown column 'Processed' in 'where clause'")
[2025-05-19T22:36:19.713+0000] {taskinstance.py:2698} ERROR - Task failed with exception
Traceback (most recent call last):
  File "/home/airflow/.local/lib/python3.8/site-packages/pandas/io/sql.py", line 2202, in execute
    cur.execute(sql, *args)
  File "/home/airflow/.local/lib/python3.8/site-packages/MySQLdb/cursors.py", line 179, in execute
    res = self._query(mogrified_query)
  File "/home/airflow/.local/lib/python3.8/site-packages/MySQLdb/cursors.py", line 330, in _query
    db.query(q)
  File "/home/airflow/.local/lib/python3.8/site-packages/MySQLdb/connections.py", line 257, in query
    _mysql.connection.query(self, query)
MySQLdb.OperationalError: (1054, "Unknown column 'Processed' in 'where clause'")

The above exception was the direct cause of the following exception:

Traceback (most recent call last):
  File "/home/airflow/.local/lib/python3.8/site-packages/airflow/models/taskinstance.py", line 433, in _execute_task
    result = execute_callable(context=context, **execute_callable_kwargs)
  File "/home/airflow/.local/lib/python3.8/site-packages/airflow/operators/python.py", line 199, in execute
    return_value = self.execute_callable()
  File "/home/airflow/.local/lib/python3.8/site-packages/airflow/operators/python.py", line 216, in execute_callable
    return self.python_callable(*self.op_args, **self.op_kwargs)
  File "/opt/airflow/dags/tasks/data_validation.py", line 109, in validate_flight_data
    df = mysql_hook.get_pandas_df(query)
  File "/home/airflow/.local/lib/python3.8/site-packages/airflow/providers/common/sql/hooks/sql.py", line 221, in get_pandas_df
    return psql.read_sql(sql, con=conn, params=parameters, **kwargs)
  File "/home/airflow/.local/lib/python3.8/site-packages/pandas/io/sql.py", line 635, in read_sql
    return pandas_sql.read_query(
  File "/home/airflow/.local/lib/python3.8/site-packages/pandas/io/sql.py", line 2266, in read_query
    cursor = self.execute(sql, params)
  File "/home/airflow/.local/lib/python3.8/site-packages/pandas/io/sql.py", line 2214, in execute
    raise ex from exc
pandas.errors.DatabaseError: Execution failed on sql 'SELECT * FROM flight_data WHERE Processed = 0': (1054, "Unknown column 'Processed' in 'where clause'")
[2025-05-19T22:36:19.724+0000] {taskinstance.py:1138} INFO - Marking task as FAILED. dag_id=flight_price_analysis, task_id=validate_data, execution_date=20250519T222604, start_date=20250519T223619, end_date=20250519T223619
[2025-05-19T22:36:19.736+0000] {standard_task_runner.py:107} ERROR - Failed to execute job 16 for task validate_data (Execution failed on sql 'SELECT * FROM flight_data WHERE Processed = 0': (1054, "Unknown column 'Processed' in 'where clause'"); 1553)
[2025-05-19T22:36:19.755+0000] {local_task_job_runner.py:234} INFO - Task exited with return code 1
[2025-05-19T22:36:19.769+0000] {taskinstance.py:3280} INFO - 0 downstream tasks scheduled from follow-on schedule check
